<?xml version="1.0"?>

<robot name="wheelchair" xmlns:xacro="http://www.ros.org/wiki/xacro" >

  <xacro:property name="robot_name" value="wheelchair" />

  <!-- wheelchairs total real world mass 154kg-->
  <!-- real mass distribution is unknown so small wheels are assumed to be 1 kg, 
       large wheels 4 kg and the rest is in the wheelchair frame-->
  <xacro:property name="wheelchair_mass" value="142" />
  <xacro:property name="front_wheel_mass" value="1"/>
  <xacro:property name="back_wheel_mass" value="4"/>
  <!-- for inertial calculations only the wheels and mass of the body as a whole has been calculated -->
  <!-- the individual inertia for each component has been neglected-->

  <xacro:property name="wheelchair_base_width" value="0.3" />
  <xacro:property name="wheelchair_base_length" value="0.55" />  

  <xacro:property name="small_wheel_radius" value="0.09" />
  <xacro:property name="large_wheel_radius" value="0.18" />
  <xacro:property name="small_wheel_thickness" value="0.045" />
  <xacro:property name="large_wheel_thickness" value="0.065" />

  <!-- 
       large wheel inerial matrix
       ixx="0.0338" ixy="0.0" ixz="0.0" iyy="0.0338" iyz="0.0" izz="0.0108"

       small wheel inirtia matrix
       ixx="0.00223" ixy="0.0" ixz="0.0" iyy="0.00223" iyz="0.0" izz="0.00125"

       wheelchair main body inertia matrix
       ixx="4.78658" ixy="0.0" ixz="0.0" iyy="3.99967" iyz="0.0" izz="5.36878"
  -->

  <material name="blue">
    <color rgba="0 0 1 1"/>
  </material>
  <material name="black">
    <color rgba="0 0 0 1"/>
  </material>
  <material name="white">
    <color rgba="1 1 1 1"/>
  </material>

  <link name="base_link"></link>

  <link name="wheelchair_base">

    <visual name="visual">
			<geometry>
				<box size="${wheelchair_base_length} ${wheelchair_base_width} 0.28"/>
			</geometry>
      <material name="black"/>
		</visual>

		<collision name="collision">
			<geometry>
				<box size="${wheelchair_base_length} ${wheelchair_base_width} 0.28"/>
			</geometry>
		</collision>

    <inertial>
			<mass value="${wheelchair_mass}"/>
          <!-- centre of inertai is moved down to be near the centr of mass, which is near the batteries and motors -->
      		<origin xyz="0 0 0" rpy=" 0 0 0"/>
          
          <!-- inertia is calculated using the height of both base and seat and the depth and width of the seat--> 
          <inertia ixx="4.78658" ixy="0.0" ixz="0.0" iyy="3.99967" iyz="0.0" izz="5.36878"/>
		</inertial>

	</link>

  <joint name="wheelchair_base_joint" type="fixed">
    <parent link="base_link"/>
    <child link="wheelchair_base"/>
    <origin rpy="0 0 0" xyz="0 0 0"/>
  </joint>

  <link name="lidar_mount">

    <visual name="visual">
			<geometry>
				<box size="0.35 0.08 0.005"/>
			</geometry>
      <material name="black"/>
		</visual>

		<collision name="collision">
			<geometry>
				<box size="0.35 0.08 0.005"/>
			</geometry>
		</collision>

	</link>


  <joint name="lidar_mount_joint" type="fixed">
    <parent link="wheelchair_base"/>
    <child link="lidar_mount"/>
    <origin rpy="0 0 0" xyz="0.34 0 -0.11"/>
  </joint>

  <link name="lidar">

    <visual name="visual">
			<geometry>
				<box size="0.097 0.07 0.055"/>
			</geometry>
      <material name="blue"/>
		</visual>

		<collision name="collision">
			<geometry>
				<box size="0.097 0.07 0.055"/>
			</geometry>
		</collision>

	</link>

  <joint name="lidar_joint" type="fixed">
    <parent link="lidar_mount"/>
    <child link="lidar"/>
    <origin rpy="0 0 0" xyz="0.135 0 -0.0275"/>
  </joint>

  <gazebo reference="lidar">

    <sensor name="lidar_A1" type="ray">
      <visualize>true</visualize>
      <update_rate>5</update_rate>
      <ray> 
        <scan>
          <horizontal>
            <samples>2000</samples>
            <resolution>1</resolution>
            <min_angle>-3.14</min_angle>
            <max_angle>3.14</max_angle>
          </horizontal>
        </scan>

        <range>
          <min>0.3</min>
          <max>12.0</max>
          <resolution>1</resolution>
        </range>
      </ray>

      <plugin name="lidar_ray_controller" filename="libgazebo_ros_laser.so">
        <frame_name>lidar</frame_name>
        <topicName>/scan</topicName>
      </plugin>
    </sensor>
  
  </gazebo>

  <link name="chair_seat">

    <visual name="visual">
			<geometry>
				<box size="0.51 0.44 0.10"/>
			</geometry>
      <material name="black"/>
		</visual>

		<collision name="collision">
			<geometry>
				<box size="0.51 0.44 0.10"/>
			</geometry>
		</collision>

	</link>

  <joint name="chair_seat_joint" type="fixed">
    <parent link="wheelchair_base"/>
    <child link="chair_seat"/>
    <origin rpy="0 0 0" xyz="0.05 0 0.19"/>
  </joint>

  <link name="right_base_block">

    <visual name="visual">
			<geometry>
				<box size="0.8 0.05 0.20"/>
			</geometry>
      <material name="black"/>
		</visual>

		<collision name="collision">
			<geometry>
				<box size="0.8 0.05 0.20"/>
			</geometry>
		</collision>

	</link>

  <joint name="right_base_block_joint" type="fixed">
    <parent link="wheelchair_base"/>
    <child link="right_base_block"/>
    <origin rpy="0 0 0" xyz="0 0.175 0.0"/>
  </joint>

  <link name="left_base_block">
  
    <visual name="visual">
			<geometry>
				<box size="0.8 0.05 0.20"/>
			</geometry>
      <material name="black"/>
		</visual>

		<collision name="collision">
			<geometry>
				<box size="0.8 0.05 0.20"/>
			</geometry>
		</collision>

	</link>

  <joint name="left_base_block_joint" type="fixed">
    <parent link="wheelchair_base"/>
    <child link="left_base_block"/>
    <origin rpy="0 0 0" xyz="0 -0.175 0.0"/>
  </joint>
  

  <link name="right_front_wheel">

    <visual>
      <origin rpy="1.57075 0 0" xyz="0 0 0"/>
      <geometry>
        <cylinder length="${small_wheel_thickness}" radius="${small_wheel_radius}"/>
      </geometry>
      <material name="white"/>
    </visual>

    <collision>
      <origin rpy="1.57075 0 0" xyz="0 0 0"/>
      <geometry>
        <cylinder length="${small_wheel_thickness}" radius="${small_wheel_radius}"/>
      </geometry>
    </collision>

    <inertial>
      <mass value="1"/>
      <inertia ixx="0.00223" ixy="0.0" ixz="0.0" iyy="0.00223" iyz="0.0" izz="0.00125"/>
    </inertial>

  </link>

  <joint name="right_front_wheel_joint" type="continuous">
    <axis rpy="0 0 0" xyz="0 1 0"/>
    <parent link="wheelchair_base"/>
    <child link="right_front_wheel"/>
    <origin rpy="0 0 0" xyz="0.35 -0.2275 -0.13"/>
  </joint>

  <link name="right_large_wheel">

    <visual>
      <origin rpy="1.57075 0 0" xyz="0 0 0"/>
      <geometry>
        <cylinder length="${large_wheel_thickness}" radius="${large_wheel_radius}"/>
      </geometry>
      <material name="white"/>
    </visual>

    <collision>
      <origin rpy="1.57075 0 0" xyz="0 0 0"/>
      <geometry>
        <cylinder length="${large_wheel_thickness}" radius="${large_wheel_radius}"/>
      </geometry>
    </collision>

    <inertial>
      <mass value="1"/>
      <inertia ixx="1.0" ixy="0.0" ixz="0.0" iyy="1.0" iyz="0.0" izz="1.0"/>
    </inertial>

  </link>

  <joint name="right_large_wheel_joint" type="continuous">
    <axis rpy="0 0 0" xyz="0 1 0"/>
    <parent link="wheelchair_base"/>
    <child link="right_large_wheel"/>
    <origin rpy="0 0 0" xyz="0 -0.2375 -0.04"/>
  </joint>

  <link name="right_back_wheel">

    <visual>
      <origin rpy="1.57075 0 0" xyz="0 0 0"/>
      <geometry>
        <cylinder length="${small_wheel_thickness}" radius="${small_wheel_radius}"/>
      </geometry>
      <material name="white"/>
    </visual>

    <collision>
      <origin rpy="1.57075 0 0" xyz="0 0 0"/>
      <geometry>
        <cylinder length="${small_wheel_thickness}" radius="${small_wheel_radius}"/>
      </geometry>
    </collision>

    <inertial>
      <mass value="1"/>
      <inertia ixx="0.0338" ixy="0.0" ixz="0.0" iyy="0.0338" iyz="0.0" izz="0.0108"/>
    </inertial>

  </link>

  <joint name="right_back_wheel_joint" type="continuous">
    <axis rpy="0 0 0" xyz="0 1 0"/>
    <parent link="wheelchair_base"/>
    <child link="right_back_wheel"/>
    <origin rpy="0 0 0" xyz="-0.35 -0.1775 -0.13"/>
  </joint>

  <link name="left_front_wheel">

    <visual>
      <origin rpy="1.57075 0 0" xyz="0 0 0"/>
      <geometry>
        <cylinder length="${small_wheel_thickness}" radius="${small_wheel_radius}"/>
      </geometry>
      <material name="white"/>
    </visual>

    <collision>
      <origin rpy="1.57075 0 0" xyz="0 0 0"/>
      <geometry>
        <cylinder length="${small_wheel_thickness}" radius="${small_wheel_radius}"/>
      </geometry>
    </collision>
    
    <inertial>
      <mass value="1"/>
      <inertia ixx="1.0" ixy="0.0" ixz="0.0" iyy="1.0" iyz="0.0" izz="1.0"/>
    </inertial>
    
  </link>

  <joint name="left_front_wheel_joint" type="continuous">
    <axis rpy="0 0 0" xyz="0 1 0"/>
    <parent link="wheelchair_base"/>
    <child link="left_front_wheel"/>
    <origin rpy="0 0 0" xyz="0.35 0.2275 -0.13"/>
  </joint>

  <link name="left_large_wheel">

    <visual>
      <origin rpy="1.57075 0 0" xyz="0 0 0"/>
      <geometry>
        <cylinder length="${large_wheel_thickness}" radius="${large_wheel_radius}"/>
      </geometry>
      <material name="white"/>
    </visual>

    <collision>
      <origin rpy="1.57075 0 0" xyz="0 0 0"/>
      <geometry>
        <cylinder length="${large_wheel_thickness}" radius="${large_wheel_radius}"/>
      </geometry>
    </collision>

    <inertial>
      <mass value="1"/>
      <inertia ixx="0.00223" ixy="0.0" ixz="0.0" iyy="0.00223" iyz="0.0" izz="0.00125"/>
    </inertial>
  </link>

  <joint name="left_large_wheel_joint" type="continuous">
    <axis rpy="0 0 0" xyz="0 1 0"/>
    <parent link="wheelchair_base"/>
    <child link="left_large_wheel"/>
    <origin rpy="0 0 0" xyz="0 0.2375 -0.04"/>
  </joint>

  <link name="left_back_wheel">

    <visual>
      <origin rpy="1.57075 0 0" xyz="0 0 0"/>
      <geometry>
        <cylinder length="${small_wheel_thickness}" radius="${small_wheel_radius}"/>
      </geometry>
      <material name="white"/>
    </visual>

    <collision>
      <origin rpy="1.57075 0 0" xyz="0 0 0"/>
      <geometry>
        <cylinder length="${small_wheel_thickness}" radius="${small_wheel_radius}"/>
      </geometry>
    </collision>

    <inertial>
      <mass value="1"/>
      <inertia ixx="0.0338" ixy="0.0" ixz="0.0" iyy="0.0338" iyz="0.0" izz="0.0108"/>
    </inertial>

  </link>

  <joint name="left_back_wheel_joint" type="continuous">
    <axis rpy="0 0 0" xyz="0 1 0"/>
    <parent link="wheelchair_base"/>
    <child link="left_back_wheel"/>
    <origin rpy="0 0 0" xyz="-0.35 0.1775 -0.13"/>
  </joint>

  <!-- wheelchair caster wheels are set to have low friction -->
  <gazebo reference="right_front_wheel">
		<mu1>0.001</mu1>
		<mu2>0.001</mu2>
	</gazebo>

  <gazebo reference="left_front_wheel">
		<mu1>0.001</mu1>
		<mu2>0.001</mu2>
	</gazebo>

  <gazebo reference="right_back_wheel">
		<mu1>0.001</mu1>
		<mu2>0.001</mu2>
	</gazebo>

  <gazebo reference="left_back_wheel">
		<mu1>0.001</mu1>
		<mu2>0.001</mu2>
	</gazebo>

  <!-- physics values for large wheels are based of values used in code examples from https://wiki.ros.org/urdf/Tutorials/Using%20a%20URDF%20in%20Gazebo -->
  <!-- max velocity is set as the radians per second needed to travel at 6 kmh with wheels of radius 16 cm-->
  <gazebo reference="right_large_wheel">
    <mu1 value="1.0"/>
    <mu2 value="0.25"/>
    <kp value="10000000.0" />
    <kd value="1.0" />
		<maxVel value = "9.26"/>
	</gazebo>

  <gazebo reference="left_large_wheel">
    <mu1 value="1.0"/>
    <mu2 value="025"/>
    <kp value="10000000.0" />
    <kd value="1.0" />
		<maxVel value = "9.26"/>
	</gazebo>

  <!-- differential drive gazebo controller-->
  <gazebo>
    
    <plugin name="differential_drive_controller" filename="libgazebo_ros_diff_drive.so">
      <updateRate>10.0</updateRate>
      <robotNamespace>/</robotNamespace>
      <robotBaseFrame>base_link</robotBaseFrame>
      <leftJoint>left_large_wheel_joint</leftJoint>
      <rightJoint>right_large_wheel_joint</rightJoint>
      <wheelSeparation>0.475</wheelSeparation>
      <wheelDiameter>0.36</wheelDiameter>

      <topicName>/cmd_vel_out</topicName>
      <commandTopic>/cmd_vel_out</commandTopic>
      <topic_name_twist>/cmd_vel_out</topic_name_twist>

      <odometryTopic>odom</odometryTopic>
      <odometryFrame>odom</odometryFrame>
      <topic_name_odometry>odom</topic_name_odometry>
      
      <!--Default values-->
      <publishTF>10</publishTF>
      <publishWheelTF>False</publishWheelTF>
      <publishWheelJointState>False</publishWheelJointState>
      <publishOdomTF>True</publishOdomTF> 

    </plugin>

  </gazebo>

</robot>
